sqlalchemy.exc.OperationalError: (psycopg2.OperationalError) SSL connection has been closed unexpectedly [SQL: SELECT cell.created_at AS cell_created_at, cell.updated_at AS cell_updated_at, cell.id AS cell_id, cell.name AS cell_name, cell.chemistry AS cell_chemistry, cell.capacity AS cell_capacity, cell.form AS cell_form FROM cell ORDER BY cell.name] (Background on this error at: https://sqlalche.me/e/20/e3q8)
Traceback:
File "/home/runner/workspace/.pythonlibs/lib/python3.11/site-packages/streamlit/runtime/scriptrunner/exec_code.py", line 121, in exec_func_with_error_handling
    result = func()
             ^^^^^^
File "/home/runner/workspace/.pythonlibs/lib/python3.11/site-packages/streamlit/runtime/scriptrunner/script_runner.py", line 648, in code_to_exec
    exec(code, module.__dict__)
File "/home/runner/workspace/streamlit_app.py", line 144, in <module>
    render_upload_page()
File "/home/runner/workspace/app/ui/refactored_upload.py", line 1581, in render_upload_page
    cells = session.query(Cell).order_by(Cell.name).all()
            ^^^^^^^^^^^^^^^^^^^^^^^^^^^^^^^^^^^^^^^^^^^^^
File "/home/runner/workspace/.pythonlibs/lib/python3.11/site-packages/sqlalchemy/orm/query.py", line 2704, in all
    return self._iter().all()  # type: ignore
           ^^^^^^^^^^^^
File "/home/runner/workspace/.pythonlibs/lib/python3.11/site-packages/sqlalchemy/orm/query.py", line 2858, in _iter
    result: Union[ScalarResult[_T], Result[_T]] = self.session.execute(
                                                  ^^^^^^^^^^^^^^^^^^^^^
File "/home/runner/workspace/.pythonlibs/lib/python3.11/site-packages/sqlmodel/orm/session.py", line 127, in execute
    return super().execute(
           ^^^^^^^^^^^^^^^^
File "/home/runner/workspace/.pythonlibs/lib/python3.11/site-packages/sqlalchemy/orm/session.py", line 2365, in execute
    return self._execute_internal(
           ^^^^^^^^^^^^^^^^^^^^^^^
File "/home/runner/workspace/.pythonlibs/lib/python3.11/site-packages/sqlalchemy/orm/session.py", line 2251, in _execute_internal
    result: Result[Any] = compile_state_cls.orm_execute_statement(
                          ^^^^^^^^^^^^^^^^^^^^^^^^^^^^^^^^^^^^^^^^
File "/home/runner/workspace/.pythonlibs/lib/python3.11/site-packages/sqlalchemy/orm/context.py", line 306, in orm_execute_statement
    result = conn.execute(
             ^^^^^^^^^^^^^
File "/home/runner/workspace/.pythonlibs/lib/python3.11/site-packages/sqlalchemy/engine/base.py", line 1416, in execute
    return meth(
           ^^^^^
File "/home/runner/workspace/.pythonlibs/lib/python3.11/site-packages/sqlalchemy/sql/elements.py", line 523, in _execute_on_connection
    return connection._execute_clauseelement(
           ^^^^^^^^^^^^^^^^^^^^^^^^^^^^^^^^^^
File "/home/runner/workspace/.pythonlibs/lib/python3.11/site-packages/sqlalchemy/engine/base.py", line 1638, in _execute_clauseelement
    ret = self._execute_context(
          ^^^^^^^^^^^^^^^^^^^^^^
File "/home/runner/workspace/.pythonlibs/lib/python3.11/site-packages/sqlalchemy/engine/base.py", line 1843, in _execute_context
    return self._exec_single_context(
           ^^^^^^^^^^^^^^^^^^^^^^^^^^
File "/home/runner/workspace/.pythonlibs/lib/python3.11/site-packages/sqlalchemy/engine/base.py", line 1983, in _exec_single_context
    self._handle_dbapi_exception(
File "/home/runner/workspace/.pythonlibs/lib/python3.11/site-packages/sqlalchemy/engine/base.py", line 2352, in _handle_dbapi_exception
    raise sqlalchemy_exception.with_traceback(exc_info[2]) from e
File "/home/runner/workspace/.pythonlibs/lib/python3.11/site-packages/sqlalchemy/engine/base.py", line 1964, in _exec_single_context
    self.dialect.do_execute(
File "/home/runner/workspace/.pythonlibs/lib/python3.11/site-packages/sqlalchemy/engine/default.py", line 945, in do_execute
    cursor.execute(statement, parameters)